Workbook

Sheet CVI - All Districts
A1: CEEW Climate Vulnerability Index — Complete India (650 Districts)
A2: V = (Exposure × Sensitivity) / Adaptive Capacity → Normalized to 0–1 via Min-Max scaling | Source: Mohanty & Wadhawan, CEEW (2021)
A4: S.No. | B4: CEEW Rank | C4: District | D4: State | E4: Zone | F4: Primary Event | G4: Exposure (E) | H4: Sensitivity (S) | I4: Adaptive Capacity (AC) | J4: Raw VI = (E×S)/AC | K4: Normalized VI (0–1) | L4: Vulnerability Category
A5: 1 | B5: 1 | C5: Dhemaji | D5: Assam | E5: North-East | F5: Flood | G5: 0.98 | H5: 0.9 | I5: 0.35 | J5: =IF(I5=0,0,(G5*H5)/I5) -> 2.52 | K5: =IF(J5=0,0,(J5-MIN(J$5:J$654))/(MAX(J$5:J$654)-MIN(J$5:J$654))) -> 1 | L5: =IF(K5=0,"Very Low",IF(K5>=0.6,"Very High",IF(K5>=0.4,"High",IF(K5>=0.2,"Moderate",IF(K5>=0.1,"Low","Very Low"))))) -> Very High
A6: 2 | B6: 1 | C6: Gajapati | D6: Odisha | E6: East | F6: Flood & Cyclone | G6: 0.875 | H6: 0.96 | I6: 0.36 | J6: =IF(I6=0,0,(G6*H6)/I6) -> 2.3333333 | K6: =IF(J6=0,0,(J6-MIN(J$5:J$654))/(MAX(J$5:J$654)-MIN(J$5:J$654))) -> 0.92592593 | L6: =IF(K6=0,"Very Low",IF(K6>=0.6,"Very High",IF(K6>=0.4,"High",IF(K6>=0.2,"Moderate",IF(K6>=0.1,"Low","Very Low"))))) -> Very High
A7: 3 | B7: 1 | C7: Khamman | D7: Telangana | E7: South | F7: Flood & Drought | G7: 0.45 | H7: 0.74 | I7: 0.14 | J7: =IF(I7=0,0,(G7*H7)/I7) -> 2.3785714 | K7: =IF(J7=0,0,(J7-MIN(J$5:J$654))/(MAX(J$5:J$654)-MIN(J$5:J$654))) -> 0.94387755 | L7: =IF(K7=0,"Very Low",IF(K7>=0.6,"Very High",IF(K7>=0.4,"High",IF(K7>=0.2,"Moderate",IF(K7>=0.1,"Low","Very Low"))))) -> Very High
A8: 4 | B8: 1 | C8: Nagaon | D8: Assam | E8: North-East | F8: Flood, Drought & Cyclone | G8: 0.83 | H8: 0.89 | I8: 0.47 | J8: =IF(I8=0,0,(G8*H8)/I8) -> 1.5717021 | K8: =IF(J8=0,0,(J8-MIN(J$5:J$654))/(MAX(J$5:J$654)-MIN(J$5:J$654))) -> 0.62369132 | L8: =IF(K8=0,"Very Low",IF(K8>=0.6,"Very High",IF(K8>=0.4,"High",IF(K8>=0.2,"Moderate",IF(K8>=0.1,"Low","Very Low"))))) -> Very High
A9: 5 | B9: 1 | C9: Sangli | D9: Maharashtra | E9: West | F9: Drought | G9: 0.82 | H9: 1 | I9: 0.47 | J9: =IF(I9=0,0,(G9*H9)/I9) -> 1.7446809 | K9: =IF(J9=0,0,(J9-MIN(J$5:J$654))/(MAX(J$5:J$654)-MIN(J$5:J$654))) -> 0.69233367 | L9: =IF(K9=0,"Very Low",IF(K9>=0.6,"Very High",IF(K9>=0.4,"High",IF(K9>=0.2,"Moderate",IF(K9>=0.1,"Low","Very Low"))))) -> Very High
A10: 6 | B10: 1 | C10: Vizianagaram | D10: Andhra Pradesh | E10: South | F10: Drought & Cyclone | G10: 0.909 | H10: 1 | I10: 0.4 | J10: =IF(I10=0,0,(G10*H10)/I10) -> 2.2725 | K10: =IF(J10=0,0,(J10-MIN(J$5:J$654))/(MAX(J$5:J$654)-MIN(J$5:J$654))) -> 0.90178571 | L10: =IF(K10=0,"Very Low",IF(K10>=0.6,"Very High",IF(K10>=0.4,"High",IF(K10>=0.2,"Moderate",IF(K10>=0.1,"Low","Very Low"))))) -> Very High
A11: 7 | B11: 2 | C11: Chennai | D11: Tamil Nadu | E11: South | F11: Flood & Cyclone | G11: 1 | H11: 0.69 | I11: 0.45 | J11: =IF(I11=0,0,(G11*H11)/I11) -> 1.5333333 | K11: =IF(J11=0,0,(J11-MIN(J$5:J$654))/(MAX(J$5:J$654)-MIN(J$5:J$654))) -> 0.60846561 | L11: =IF(K11=0,"Very Low",IF(K11>=0.6,"Very High",IF(K11>=0.4,"High",IF(K11>=0.2,"Moderate",IF(K11>=0.1,"Low","Very Low"))))) -> Very High
A12: 8 | B12: 3 | C12: Imphal East | D12: Manipur | E12: North-East | F12: Flood & Cyclone | G12: 0.72 | H12: 1 | I12: 0.49 | J12: =IF(I12=0,0,(G12*H12)/I12) -> 1.4693878 | K12: =IF(J12=0,0,(J12-MIN(J$5:J$654))/(MAX(J$5:J$654)-MIN(J$5:J$654))) -> 0.58309038 | L12: =IF(K12=0,"Very Low",IF(K12>=0.6,"Very High",IF(K12>=0.4,"High",IF(K12>=0.2,"Moderate",IF(K12>=0.1,"Low","Very Low"))))) -> High
A13: 9 | B13: 3 | C13: Madhepura | D13: Bihar | E13: East | F13: Flood & Drought | G13: 0.86 | H13: 0.75 | I13: 0.29 | J13: =IF(I13=0,0,(G13*H13)/I13) -> 2.2241379 | K13: =IF(J13=0,0,(J13-MIN(J$5:J$654))/(MAX(J$5:J$654)-MIN(J$5:J$654))) -> 0.88259442 | L13: =IF(K13=0,"Very Low",IF(K13>=0.6,"Very High",IF(K13>=0.4,"High",IF(K13>=0.2,"Moderate",IF(K13>=0.1,"Low","Very Low"))))) -> Very High
A14: 10 | B14: 4 | C14: Banka | D14: Bihar | E14: East | F14: Flood & Cyclone | G14: 0.61 | H14: 0.77 | I14: 0.32 | J14: =IF(I14=0,0,(G14*H14)/I14) -> 1.4678125 | K14: =IF(J14=0,0,(J14-MIN(J$5:J$654))/(MAX(J$5:J$654)-MIN(J$5:J$654))) -> 0.58246528 | L14: =IF(K14=0,"Very Low",IF(K14>=0.6,"Very High",IF(K14>=0.4,"High",IF(K14>=0.2,"Moderate",IF(K14>=0.1,"Low","Very Low"))))) -> High
A15: 11 | B15: 4 | C15: Sitamarhi | D15: Bihar | E15: East | F15: Flood & Drought | G15: 0.97 | H15: 0.71 | I15: 0.31 | J15: =IF(I15=0,0,(G15*H15)/I15) -> 2.2216129 | K15: =IF(J15=0,0,(J15-MIN(J$5:J$654))/(MAX(J$5:J$654)-MIN(J$5:J$654))) -> 0.88159242 | L15: =IF(K15=0,"Very Low",IF(K15>=0.6,"Very High",IF(K15>=0.4,"High",IF(K15>=0.2,"Moderate",IF(K15>=0.1,"Low","Very Low"))))) -> Very High
A16: 12 | B16: 5 | C16: Jaisalmer | D16: Rajasthan | E16: West | F16: Drought | G16: 0.99 | H16: 0.69 | I16: 0.42 | J16: =IF(I16=0,0,(G16*H16)/I16) -> 1.6264286 | K16: =IF(J16=0,0,(J16-MIN(J$5:J$654))/(MAX(J$5:J$654)-MIN(J$5:J$654))) -> 0.64540816 | L16: =IF(K16=0,"Very Low",IF(K16>=0.6,"Very High",IF(K16>=0.4,"High",IF(K16>=0.2,"Moderate",IF(K16>=0.1,"Low","Very Low"))))) -> Very High
... A475: 471 | B475: 272 | C475: Yanam | D475: Puducherry | E475: South | F475: Cyclone | G475: 0 | H475: 0 | I475: 0.47 | J475: =IF(I475=0,0,(G475*H475)/I475) -> 0 | K475: =IF(J475=0,0,(J475-MIN(J$5:J$654))/(MAX(J$5:J$654)-MIN(J$5:J$654))) -> 0 | L475: =IF(K475=0,"Very Low",IF(K475>=0.6,"Very High",IF(K475>=0.4,"High",IF(K475>=0.2,"Moderate",IF(K475>=0.1,"Low","Very Low"))))) -> Very Low
A476: 472 | B476: — | C476: Alirajpur | D476: Madhya Pradesh | E476: Central | F476: No Data Available | G476: No Data | H476: No Data | I476: No Data | J476: — | K476: — | L476: No Data Available
A477: 473 | B477: — | C477: Almora | D477: Uttarakhand | E477: North | F477: No Data Available | G477: No Data | H477: No Data | I477: No Data | J477: — | K477: — | L477: No Data Available
A478: 474 | B478: — | C478: Amritsar | D478: Punjab | E478: North | F478: No Data Available | G478: No Data | H478: No Data | I478: No Data | J478: — | K478: — | L478: No Data Available
A479: 475 | B479: — | C479: Anjaw | D479: Arunachal Pradesh | E479: North-East | F479: No Data Available | G479: No Data | H479: No Data | I479: No Data | J479: — | K479: — | L479: No Data Available
A480: 476 | B480: — | C480: Badgam | D480: Jammu & Kashmir | E480: North | F480: No Data Available | G480: No Data | H480: No Data | I480: No Data | J480: — | K480: — | L480: No Data Available
A481: 477 | B481: — | C481: Bageshwar | D481: Uttarakhand | E481: North | F481: No Data Available | G481: No Data | H481: No Data | I481: No Data | J481: — | K481: — | L481: No Data Available
A482: 478 | B482: — | C482: Baghpat | D482: Uttar Pradesh | E482: North | F482: No Data Available | G482: No Data | H482: No Data | I482: No Data | J482: — | K482: — | L482: No Data Available
A483: 479 | B483: — | C483: Baksa | D483: Assam | E483: North-East | F483: No Data Available | G483: No Data | H483: No Data | I483: No Data | J483: — | K483: — | L483: No Data Available
A484: 480 | B484: — | C484: Baramulla | D484: Jammu & Kashmir | E484: North | F484: No Data Available | G484: No Data | H484: No Data | I484: No Data | J484: — | K484: — | L484: No Data Available
A485: 481 | B485: — | C485: Bargarh | D485: Odisha | E485: East | F485: No Data Available | G485: No Data | H485: No Data | I485: No Data | J485: — | K485: — | L485: No Data Available
A486: 482 | B486: — | C486: Barnala | D486: Punjab | E486: North | F486: No Data Available | G486: No Data | H486: No Data | I486: No Data | J486: — | K486: — | L486: No Data Available
A487: 483 | B487: — | C487: Barwani | D487: Madhya Pradesh | E487: Central | F487: No Data Available | G487: No Data | H487: No Data | I487: No Data | J487: — | K487: — | L487: No Data Available
... A654: 650 | B654: — | C654: Zunheboto | D654: Nagaland | E654: North-East | F654: No Data Available | G654: No Data | H654: No Data | I654: No Data | J654: — | K654: — | L654: No Data Available

Sheet State Summary
A1: State-wise CVI Summary
A3: State | B3: Zone | C3: Total Districts | D3: Hotspot Districts | E3: No Data Districts | F3: % Hotspot | G3: Avg Normalized VI | H3: Max Normalized VI | I3: Most Vulnerable District
A4: Andaman & Nicobar | B4: Island | C4: =COUNTIF('CVI - All Districts'!D5:D654,"Andaman & Nicobar") -> 3 | D4: =COUNTIFS('CVI - All Districts'!D5:D654,"Andaman & Nicobar",'CVI - All Districts'!L5:L654,"<>No Data Available") -> 2 | E4: =C4-D4 -> 1 | F4: =IF(C4=0,0,D4/C4) -> 0.66666667 | G4: =IFERROR(AVERAGEIFS('CVI - All Districts'!K5:K654,'CVI - All Districts'!D5:D654,"Andaman & Nicobar",'CVI - All Districts'!L5:L654,"<>No Data Available"),0) -> 0 | H4: =IFERROR(maxifs('CVI - All Districts'!K5:K654,'CVI - All Districts'!D5:D654,"Andaman & Nicobar"),0) -> 0 | I4: =IFERROR(INDEX('CVI - All Districts'!C5:C654,MATCH(maxifs('CVI - All Districts'!K5:K654,'CVI - All Districts'!D5:D654,"Andaman & Nicobar"),'CVI - All Districts'!K5:K654,0)),"—") -> —
A5: Andhra Pradesh | B5: South | C5: =COUNTIF('CVI - All Districts'!D5:D654,"Andhra Pradesh") -> 13 | D5: =COUNTIFS('CVI - All Districts'!D5:D654,"Andhra Pradesh",'CVI - All Districts'!L5:L654,"<>No Data Available") -> 13 | E5: =C5-D5 -> 0 | F5: =IF(C5=0,0,D5/C5) -> 1 | G5: =IFERROR(AVERAGEIFS('CVI - All Districts'!K5:K654,'CVI - All Districts'!D5:D654,"Andhra Pradesh",'CVI - All Districts'!L5:L654,"<>No Data Available"),0) -> 0.4525969 | H5: =IFERROR(maxifs('CVI - All Districts'!K5:K654,'CVI - All Districts'!D5:D654,"Andhra Pradesh"),0) -> 0 | I5: =IFERROR(INDEX('CVI - All Districts'!C5:C654,MATCH(maxifs('CVI - All Districts'!K5:K654,'CVI - All Districts'!D5:D654,"Andhra Pradesh"),'CVI - All Districts'!K5:K654,0)),"—") -> —
A6: Arunachal Pradesh | B6: North-East | C6: =COUNTIF('CVI - All Districts'!D5:D654,"Arunachal Pradesh") -> 16 | D6: =COUNTIFS('CVI - All Districts'!D5:D654,"Arunachal Pradesh",'CVI - All Districts'!L5:L654,"<>No Data Available") -> 4 | E6: =C6-D6 -> 12 | F6: =IF(C6=0,0,D6/C6) -> 0.25 | G6: =IFERROR(AVERAGEIFS('CVI - All Districts'!K5:K654,'CVI - All Districts'!D5:D654,"Arunachal Pradesh",'CVI - All Districts'!L5:L654,"<>No Data Available"),0) -> 0.50043785 | H6: =IFERROR(maxifs('CVI - All Districts'!K5:K654,'CVI - All Districts'!D5:D654,"Arunachal Pradesh"),0) -> 0 | I6: =IFERROR(INDEX('CVI - All Districts'!C5:C654,MATCH(maxifs('CVI - All Districts'!K5:K654,'CVI - All Districts'!D5:D654,"Arunachal Pradesh"),'CVI - All Districts'!K5:K654,0)),"—") -> —
A7: Assam | B7: North-East | C7: =COUNTIF('CVI - All Districts'!D5:D654,"Assam") -> 27 | D7: =COUNTIFS('CVI - All Districts'!D5:D654,"Assam",'CVI - All Districts'!L5:L654,"<>No Data Available") -> 23 | E7: =C7-D7 -> 4 | F7: =IF(C7=0,0,D7/C7) -> 0.85185185 | G7: =IFERROR(AVERAGEIFS('CVI - All Districts'!K5:K654,'CVI - All Districts'!D5:D654,"Assam",'CVI - All Districts'!L5:L654,"<>No Data Available"),0) -> 0.58728278 | H7: =IFERROR(maxifs('CVI - All Districts'!K5:K654,'CVI - All Districts'!D5:D654,"Assam"),0) -> 0 | I7: =IFERROR(INDEX('CVI - All Districts'!C5:C654,MATCH(maxifs('CVI - All Districts'!K5:K654,'CVI - All Districts'!D5:D654,"Assam"),'CVI - All Districts'!K5:K654,0)),"—") -> —
A8: Bihar | B8: East | C8: =COUNTIF('CVI - All Districts'!D5:D654,"Bihar") -> 39 | D8: =COUNTIFS('CVI - All Districts'!D5:D654,"Bihar",'CVI - All Districts'!L5:L654,"<>No Data Available") -> 38 | E8: =C8-D8 -> 1 | F8: =IF(C8=0,0,D8/C8) -> 0.97435897 | G8: =IFERROR(AVERAGEIFS('CVI - All Districts'!K5:K654,'CVI - All Districts'!D5:D654,"Bihar",'CVI - All Districts'!L5:L654,"<>No Data Available"),0) -> 0.39134442 | H8: =IFERROR(maxifs('CVI - All Districts'!K5:K654,'CVI - All Districts'!D5:D654,"Bihar"),0) -> 0 | I8: =IFERROR(INDEX('CVI - All Districts'!C5:C654,MATCH(maxifs('CVI - All Districts'!K5:K654,'CVI - All Districts'!D5:D654,"Bihar"),'CVI - All Districts'!K5:K654,0)),"—") -> —
A9: Chandigarh | B9: North | C9: =COUNTIF('CVI - All Districts'!D5:D654,"Chandigarh") -> 1 | D9: =COUNTIFS('CVI - All Districts'!D5:D654,"Chandigarh",'CVI - All Districts'!L5:L654,"<>No Data Available") -> 1 | E9: =C9-D9 -> 0 | F9: =IF(C9=0,0,D9/C9) -> 1 | G9: =IFERROR(AVERAGEIFS('CVI - All Districts'!K5:K654,'CVI - All Districts'!D5:D654,"Chandigarh",'CVI - All Districts'!L5:L654,"<>No Data Available"),0) -> 0 | H9: =IFERROR(maxifs('CVI - All Districts'!K5:K654,'CVI - All Districts'!D5:D654,"Chandigarh"),0) -> 0 | I9: =IFERROR(INDEX('CVI - All Districts'!C5:C654,MATCH(maxifs('CVI - All Districts'!K5:K654,'CVI - All Districts'!D5:D654,"Chandigarh"),'CVI - All Districts'!K5:K654,0)),"—") -> —
A10: Chhattisgarh | B10: Central | C10: =COUNTIF('CVI - All Districts'!D5:D654,"Chhattisgarh") -> 18 | D10: =COUNTIFS('CVI - All Districts'!D5:D654,"Chhattisgarh",'CVI - All Districts'!L5:L654,"<>No Data Available") -> 13 | E10: =C10-D10 -> 5 | F10: =IF(C10=0,0,D10/C10) -> 0.72222222 | G10: =IFERROR(AVERAGEIFS('CVI - All Districts'!K5:K654,'CVI - All Districts'!D5:D654,"Chhattisgarh",'CVI - All Districts'!L5:L654,"<>No Data Available"),0) -> 0.06764046 | H10: =IFERROR(maxifs('CVI - All Districts'!K5:K654,'CVI - All Districts'!D5:D654,"Chhattisgarh"),0) -> 0 | I10: =IFERROR(INDEX('CVI - All Districts'!C5:C654,MATCH(maxifs('CVI - All Districts'!K5:K654,'CVI - All Districts'!D5:D654,"Chhattisgarh"),'CVI - All Districts'!K5:K654,0)),"—") -> —
A11: Dadra & Nagar Haveli | B11: West | C11: =COUNTIF('CVI - All Districts'!D5:D654,"Dadra & Nagar Haveli") -> 1 | D11: =COUNTIFS('CVI - All Districts'!D5:D654,"Dadra & Nagar Haveli",'CVI - All Districts'!L5:L654,"<>No Data Available") -> 0 | E11: =C11-D11 -> 1 | F11: =IF(C11=0,0,D11/C11) -> 0 | G11: =IFERROR(AVERAGEIFS('CVI - All Districts'!K5:K654,'CVI - All Districts'!D5:D654,"Dadra & Nagar Haveli",'CVI - All Districts'!L5:L654,"<>No Data Available"),0) -> 0 | H11: =IFERROR(maxifs('CVI - All Districts'!K5:K654,'CVI - All Districts'!D5:D654,"Dadra & Nagar Haveli"),0) -> 0 | I11: =IFERROR(INDEX('CVI - All Districts'!C5:C654,MATCH(maxifs('CVI - All Districts'!K5:K654,'CVI - All Districts'!D5:D654,"Dadra & Nagar Haveli"),'CVI - All Districts'!K5:K654,0)),"—") -> —
A12: Daman & Diu | B12: West | C12: =COUNTIF('CVI - All Districts'!D5:D654,"Daman & Diu") -> 2 | D12: =COUNTIFS('CVI - All Districts'!D5:D654,"Daman & Diu",'CVI - All Districts'!L5:L654,"<>No Data Available") -> 0 | E12: =C12-D12 -> 2 | F12: =IF(C12=0,0,D12/C12) -> 0 | G12: =IFERROR(AVERAGEIFS('CVI - All Districts'!K5:K654,'CVI - All Districts'!D5:D654,"Daman & Diu",'CVI - All Districts'!L5:L654,"<>No Data Available"),0) -> 0 | H12: =IFERROR(maxifs('CVI - All Districts'!K5:K654,'CVI - All Districts'!D5:D654,"Daman & Diu"),0) -> 0 | I12: =IFERROR(INDEX('CVI - All Districts'!C5:C654,MATCH(maxifs('CVI - All Districts'!K5:K654,'CVI - All Districts'!D5:D654,"Daman & Diu"),'CVI - All Districts'!K5:K654,0)),"—") -> —
A13: Goa | B13: West | C13: =COUNTIF('CVI - All Districts'!D5:D654,"Goa") -> 2 | D13: =COUNTIFS('CVI - All Districts'!D5:D654,"Goa",'CVI - All Districts'!L5:L654,"<>No Data Available") -> 2 | E13: =C13-D13 -> 0 | F13: =IF(C13=0,0,D13/C13) -> 1 | G13: =IFERROR(AVERAGEIFS('CVI - All Districts'!K5:K654,'CVI - All Districts'!D5:D654,"Goa",'CVI - All Districts'!L5:L654,"<>No Data Available"),0) -> 0 | H13: =IFERROR(maxifs('CVI - All Districts'!K5:K654,'CVI - All Districts'!D5:D654,"Goa"),0) -> 0 | I13: =IFERROR(INDEX('CVI - All Districts'!C5:C654,MATCH(maxifs('CVI - All Districts'!K5:K654,'CVI - All Districts'!D5:D654,"Goa"),'CVI - All Districts'!K5:K654,0)),"—") -> —
A14: Gujarat | B14: West | C14: =COUNTIF('CVI - All Districts'!D5:D654,"Gujarat") -> 26 | D14: =COUNTIFS('CVI - All Districts'!D5:D654,"Gujarat",'CVI - All Districts'!L5:L654,"<>No Data Available") -> 21 | E14: =C14-D14 -> 5 | F14: =IF(C14=0,0,D14/C14) -> 0.80769231 | G14: =IFERROR(AVERAGEIFS('CVI - All Districts'!K5:K654,'CVI - All Districts'!D5:D654,"Gujarat",'CVI - All Districts'!L5:L654,"<>No Data Available"),0) -> 0.19674104 | H14: =IFERROR(maxifs('CVI - All Districts'!K5:K654,'CVI - All Districts'!D5:D654,"Gujarat"),0) -> 0 | I14: =IFERROR(INDEX('CVI - All Districts'!C5:C654,MATCH(maxifs('CVI - All Districts'!K5:K654,'CVI - All Districts'!D5:D654,"Gujarat"),'CVI - All Districts'!K5:K654,0)),"—") -> —
A15: Haryana | B15: North | C15: =COUNTIF('CVI - All Districts'!D5:D654,"Haryana") -> 21 | D15: =COUNTIFS('CVI - All Districts'!D5:D654,"Haryana",'CVI - All Districts'!L5:L654,"<>No Data Available") -> 10 | E15: =C15-D15 -> 11 | F15: =IF(C15=0,0,D15/C15) -> 0.47619048 | G15: =IFERROR(AVERAGEIFS('CVI - All Districts'!K5:K654,'CVI - All Districts'!D5:D654,"Haryana",'CVI - All Districts'!L5:L654,"<>No Data Available"),0) -> 0.08500421 | H15: =IFERROR(maxifs('CVI - All Districts'!K5:K654,'CVI - All Districts'!D5:D654,"Haryana"),0) -> 0 | I15: =IFERROR(INDEX('CVI - All Districts'!C5:C654,MATCH(maxifs('CVI - All Districts'!K5:K654,'CVI - All Districts'!D5:D654,"Haryana"),'CVI - All Districts'!K5:K654,0)),"—") -> —
A16: Himachal Pradesh | B16: North | C16: =COUNTIF('CVI - All Districts'!D5:D654,"Himachal Pradesh") -> 12 | D16: =COUNTIFS('CVI - All Districts'!D5:D654,"Himachal Pradesh",'CVI - All Districts'!L5:L654,"<>No Data Available") -> 8 | E16: =C16-D16 -> 4 | F16: =IF(C16=0,0,D16/C16) -> 0.66666667 | G16: =IFERROR(AVERAGEIFS('CVI - All Districts'!K5:K654,'CVI - All Districts'!D5:D654,"Himachal Pradesh",'CVI - All Districts'!L5:L654,"<>No Data Available"),0) -> 0.29772571 | H16: =IFERROR(maxifs('CVI - All Districts'!K5:K654,'CVI - All Districts'!D5:D654,"Himachal Pradesh"),0) -> 0 | I16: =IFERROR(INDEX('CVI - All Districts'!C5:C654,MATCH(maxifs('CVI - All Districts'!K5:K654,'CVI - All Districts'!D5:D654,"Himachal Pradesh"),'CVI - All Districts'!K5:K654,0)),"—") -> —
A17: Jammu & Kashmir | B17: North | C17: =COUNTIF('CVI - All Districts'!D5:D654,"Jammu & Kashmir") -> 22 | D17: =COUNTIFS('CVI - All Districts'!D5:D654,"Jammu & Kashmir",'CVI - All Districts'!L5:L654,"<>No Data Available") -> 9 | E17: =C17-D17 -> 13 | F17: =IF(C17=0,0,D17/C17) -> 0.40909091 | G17: =IFERROR(AVERAGEIFS('CVI - All Districts'!K5:K654,'CVI - All Districts'!D5:D654,"Jammu & Kashmir",'CVI - All Districts'!L5:L654,"<>No Data Available"),0) -> 0.29940418 | H17: =IFERROR(maxifs('CVI - All Districts'!K5:K654,'CVI - All Districts'!D5:D654,"Jammu & Kashmir"),0) -> 0 | I17: =IFERROR(INDEX('CVI - All Districts'!C5:C654,MATCH(maxifs('CVI - All Districts'!K5:K654,'CVI - All Districts'!D5:D654,"Jammu & Kashmir"),'CVI - All Districts'!K5:K654,0)),"—") -> —
A18: Jharkhand | B18: East | C18: =COUNTIF('CVI - All Districts'!D5:D654,"Jharkhand") -> 24 | D18: =COUNTIFS('CVI - All Districts'!D5:D654,"Jharkhand",'CVI - All Districts'!L5:L654,"<>No Data Available") -> 19 | E18: =C18-D18 -> 5 | F18: =IF(C18=0,0,D18/C18) -> 0.79166667 | G18: =IFERROR(AVERAGEIFS('CVI - All Districts'!K5:K654,'CVI - All Districts'!D5:D654,"Jharkhand",'CVI - All Districts'!L5:L654,"<>No Data Available"),0) -> 0.024127866 | H18: =IFERROR(maxifs('CVI - All Districts'!K5:K654,'CVI - All Districts'!D5:D654,"Jharkhand"),0) -> 0 | I18: =IFERROR(INDEX('CVI - All Districts'!C5:C654,MATCH(maxifs('CVI - All Districts'!K5:K654,'CVI - All Districts'!D5:D654,"Jharkhand"),'CVI - All Districts'!K5:K654,0)),"—") -> —
A19: Karnataka | B19: South | C19: =COUNTIF('CVI - All Districts'!D5:D654,"Karnataka") -> 29 | D19: =COUNTIFS('CVI - All Districts'!D5:D654,"Karnataka",'CVI - All Districts'!L5:L654,"<>No Data Available") -> 29 | E19: =C19-D19 -> 0 | F19: =IF(C19=0,0,D19/C19) -> 1 | G19: =IFERROR(AVERAGEIFS('CVI - All Districts'!K5:K654,'CVI - All Districts'!D5:D654,"Karnataka",'CVI - All Districts'!L5:L654,"<>No Data Available"),0) -> 0.26676452 | H19: =IFERROR(maxifs('CVI - All Districts'!K5:K654,'CVI - All Districts'!D5:D654,"Karnataka"),0) -> 0 | I19: =IFERROR(INDEX('CVI - All Districts'!C5:C654,MATCH(maxifs('CVI - All Districts'!K5:K654,'CVI - All Districts'!D5:D654,"Karnataka"),'CVI - All Districts'!K5:K654,0)),"—") -> —
A20: Kerala | B20: South | C20: =COUNTIF('CVI - All Districts'!D5:D654,"Kerala") -> 14 | D20: =COUNTIFS('CVI - All Districts'!D5:D654,"Kerala",'CVI - All Districts'!L5:L654,"<>No Data Available") -> 14 | E20: =C20-D20 -> 0 | F20: =IF(C20=0,0,D20/C20) -> 1 | G20: =IFERROR(AVERAGEIFS('CVI - All Districts'!K5:K654,'CVI - All Districts'!D5:D654,"Kerala",'CVI - All Districts'!L5:L654,"<>No Data Available"),0) -> 0.20431848 | H20: =IFERROR(maxifs('CVI - All Districts'!K5:K654,'CVI - All Districts'!D5:D654,"Kerala"),0) -> 0 | I20: =IFERROR(INDEX('CVI - All Districts'!C5:C654,MATCH(maxifs('CVI - All Districts'!K5:K654,'CVI - All Districts'!D5:D654,"Kerala"),'CVI - All Districts'!K5:K654,0)),"—") -> —
A21: Lakshadweep | B21: Island | C21: =COUNTIF('CVI - All Districts'!D5:D654,"Lakshadweep") -> 1 | D21: =COUNTIFS('CVI - All Districts'!D5:D654,"Lakshadweep",'CVI - All Districts'!L5:L654,"<>No Data Available") -> 0 | E21: =C21-D21 -> 1 | F21: =IF(C21=0,0,D21/C21) -> 0 | G21: =IFERROR(AVERAGEIFS('CVI - All Districts'!K5:K654,'CVI - All Districts'!D5:D654,"Lakshadweep",'CVI - All Districts'!L5:L654,"<>No Data Available"),0) -> 0 | H21: =IFERROR(maxifs('CVI - All Districts'!K5:K654,'CVI - All Districts'!D5:D654,"Lakshadweep"),0) -> 0 | I21: =IFERROR(INDEX('CVI - All Districts'!C5:C654,MATCH(maxifs('CVI - All Districts'!K5:K654,'CVI - All Districts'!D5:D654,"Lakshadweep"),'CVI - All Districts'!K5:K654,0)),"—") -> —
A22: Madhya Pradesh | B22: Central | C22: =COUNTIF('CVI - All Districts'!D5:D654,"Madhya Pradesh") -> 50 | D22: =COUNTIFS('CVI - All Districts'!D5:D654,"Madhya Pradesh",'CVI - All Districts'!L5:L654,"<>No Data Available") -> 37 | E22: =C22-D22 -> 13 | F22: =IF(C22=0,0,D22/C22) -> 0.74 | G22: =IFERROR(AVERAGEIFS('CVI - All Districts'!K5:K654,'CVI - All Districts'!D5:D654,"Madhya Pradesh",'CVI - All Districts'!L5:L654,"<>No Data Available"),0) -> 0.11413154 | H22: =IFERROR(maxifs('CVI - All Districts'!K5:K654,'CVI - All Districts'!D5:D654,"Madhya Pradesh"),0) -> 0 | I22: =IFERROR(INDEX('CVI - All Districts'!C5:C654,MATCH(maxifs('CVI - All Districts'!K5:K654,'CVI - All Districts'!D5:D654,"Madhya Pradesh"),'CVI - All Districts'!K5:K654,0)),"—") -> —
A23: Maharashtra | B23: West | C23: =COUNTIF('CVI - All Districts'!D5:D654,"Maharashtra") -> 36 | D23: =COUNTIFS('CVI - All Districts'!D5:D654,"Maharashtra",'CVI - All Districts'!L5:L654,"<>No Data Available") -> 33 | E23: =C23-D23 -> 3 | F23: =IF(C23=0,0,D23/C23) -> 0.91666667 | G23: =IFERROR(AVERAGEIFS('CVI - All Districts'!K5:K654,'CVI - All Districts'!D5:D654,"Maharashtra",'CVI - All Districts'!L5:L654,"<>No Data Available"),0) -> 0.31918151 | H23: =IFERROR(maxifs('CVI - All Districts'!K5:K654,'CVI - All Districts'!D5:D654,"Maharashtra"),0) -> 0 | I23: =IFERROR(INDEX('CVI - All Districts'!C5:C654,MATCH(maxifs('CVI - All Districts'!K5:K654,'CVI - All Districts'!D5:D654,"Maharashtra"),'CVI - All Districts'!K5:K654,0)),"—") -> —
A24: Manipur | B24: North-East | C24: =COUNTIF('CVI - All Districts'!D5:D654,"Manipur") -> 9 | D24: =COUNTIFS('CVI - All Districts'!D5:D654,"Manipur",'CVI - All Districts'!L5:L654,"<>No Data Available") -> 5 | E24: =C24-D24 -> 4 | F24: =IF(C24=0,0,D24/C24) -> 0.55555556 | G24: =IFERROR(AVERAGEIFS('CVI - All Districts'!K5:K654,'CVI - All Districts'!D5:D654,"Manipur",'CVI - All Districts'!L5:L654,"<>No Data Available"),0) -> 0.37512915 | H24: =IFERROR(maxifs('CVI - All Districts'!K5:K654,'CVI - All Districts'!D5:D654,"Manipur"),0) -> 0 | I24: =IFERROR(INDEX('CVI - All Districts'!C5:C654,MATCH(maxifs('CVI - All Districts'!K5:K654,'CVI - All Districts'!D5:D654,"Manipur"),'CVI - All Districts'!K5:K654,0)),"—") -> —
A25: Meghalaya | B25: North-East | C25: =COUNTIF('CVI - All Districts'!D5:D654,"Meghalaya") -> 10 | D25: =COUNTIFS('CVI - All Districts'!D5:D654,"Meghalaya",'CVI - All Districts'!L5:L654,"<>No Data Available") -> 1 | E25: =C25-D25 -> 9 | F25: =IF(C25=0,0,D25/C25) -> 0.1 | G25: =IFERROR(AVERAGEIFS('CVI - All Districts'!K5:K654,'CVI - All Districts'!D5:D654,"Meghalaya",'CVI - All Districts'!L5:L654,"<>No Data Available"),0) -> 0 | H25: =IFERROR(maxifs('CVI - All Districts'!K5:K654,'CVI - All Districts'!D5:D654,"Meghalaya"),0) -> 0 | I25: =IFERROR(INDEX('CVI - All Districts'!C5:C654,MATCH(maxifs('CVI - All Districts'!K5:K654,'CVI - All Districts'!D5:D654,"Meghalaya"),'CVI - All Districts'!K5:K654,0)),"—") -> —
A26: Mizoram | B26: North-East | C26: =COUNTIF('CVI - All Districts'!D5:D654,"Mizoram") -> 8 | D26: =COUNTIFS('CVI - All Districts'!D5:D654,"Mizoram",'CVI - All Districts'!L5:L654,"<>No Data Available") -> 1 | E26: =C26-D26 -> 7 | F26: =IF(C26=0,0,D26/C26) -> 0.125 | G26: =IFERROR(AVERAGEIFS('CVI - All Districts'!K5:K654,'CVI - All Districts'!D5:D654,"Mizoram",'CVI - All Districts'!L5:L654,"<>No Data Available"),0) -> 0 | H26: =IFERROR(maxifs('CVI - All Districts'!K5:K654,'CVI - All Districts'!D5:D654,"Mizoram"),0) -> 0 | I26: =IFERROR(INDEX('CVI - All Districts'!C5:C654,MATCH(maxifs('CVI - All Districts'!K5:K654,'CVI - All Districts'!D5:D654,"Mizoram"),'CVI - All Districts'!K5:K654,0)),"—") -> —
A27: NCT Delhi | B27: North | C27: =COUNTIF('CVI - All Districts'!D5:D654,"NCT Delhi") -> 9 | D27: =COUNTIFS('CVI - All Districts'!D5:D654,"NCT Delhi",'CVI - All Districts'!L5:L654,"<>No Data Available") -> 1 | E27: =C27-D27 -> 8 | F27: =IF(C27=0,0,D27/C27) -> 0.11111111 | G27: =IFERROR(AVERAGEIFS('CVI - All Districts'!K5:K654,'CVI - All Districts'!D5:D654,"NCT Delhi",'CVI - All Districts'!L5:L654,"<>No Data Available"),0) -> 0.16666667 | H27: =IFERROR(maxifs('CVI - All Districts'!K5:K654,'CVI - All Districts'!D5:D654,"NCT Delhi"),0) -> 0 | I27: =IFERROR(INDEX('CVI - All Districts'!C5:C654,MATCH(maxifs('CVI - All Districts'!K5:K654,'CVI - All Districts'!D5:D654,"NCT Delhi"),'CVI - All Districts'!K5:K654,0)),"—") -> —
A28: Nagaland | B28: North-East | C28: =COUNTIF('CVI - All Districts'!D5:D654,"Nagaland") -> 11 | D28: =COUNTIFS('CVI - All Districts'!D5:D654,"Nagaland",'CVI - All Districts'!L5:L654,"<>No Data Available") -> 2 | E28: =C28-D28 -> 9 | F28: =IF(C28=0,0,D28/C28) -> 0.18181818 | G28: =IFERROR(AVERAGEIFS('CVI - All Districts'!K5:K654,'CVI - All Districts'!D5:D654,"Nagaland",'CVI - All Districts'!L5:L654,"<>No Data Available"),0) -> 0.29071485 | H28: =IFERROR(maxifs('CVI - All Districts'!K5:K654,'CVI - All Districts'!D5:D654,"Nagaland"),0) -> 0 | I28: =IFERROR(INDEX('CVI - All Districts'!C5:C654,MATCH(maxifs('CVI - All Districts'!K5:K654,'CVI - All Districts'!D5:D654,"Nagaland"),'CVI - All Districts'!K5:K654,0)),"—") -> —
A29: Odisha | B29: East | C29: =COUNTIF('CVI - All Districts'!D5:D654,"Odisha") -> 30 | D29: =COUNTIFS('CVI - All Districts'!D5:D654,"Odisha",'CVI - All Districts'!L5:L654,"<>No Data Available") -> 22 | E29: =C29-D29 -> 8 | F29: =IF(C29=0,0,D29/C29) -> 0.73333333 | G29: =IFERROR(AVERAGEIFS('CVI - All Districts'!K5:K654,'CVI - All Districts'!D5:D654,"Odisha",'CVI - All Districts'!L5:L654,"<>No Data Available"),0) -> 0.29368459 | H29: =IFERROR(maxifs('CVI - All Districts'!K5:K654,'CVI - All Districts'!D5:D654,"Odisha"),0) -> 0 | I29: =IFERROR(INDEX('CVI - All Districts'!C5:C654,MATCH(maxifs('CVI - All Districts'!K5:K654,'CVI - All Districts'!D5:D654,"Odisha"),'CVI - All Districts'!K5:K654,0)),"—") -> —
A30: Puducherry | B30: South | C30: =COUNTIF('CVI - All Districts'!D5:D654,"Puducherry") -> 4 | D30: =COUNTIFS('CVI - All Districts'!D5:D654,"Puducherry",'CVI - All Districts'!L5:L654,"<>No Data Available") -> 2 | E30: =C30-D30 -> 2 | F30: =IF(C30=0,0,D30/C30) -> 0.5 | G30: =IFERROR(AVERAGEIFS('CVI - All Districts'!K5:K654,'CVI - All Districts'!D5:D654,"Puducherry",'CVI - All Districts'!L5:L654,"<>No Data Available"),0) -> 0.069940476 | H30: =IFERROR(maxifs('CVI - All Districts'!K5:K654,'CVI - All Districts'!D5:D654,"Puducherry"),0) -> 0 | I30: =IFERROR(INDEX('CVI - All Districts'!C5:C654,MATCH(maxifs('CVI - All Districts'!K5:K654,'CVI - All Districts'!D5:D654,"Puducherry"),'CVI - All Districts'!K5:K654,0)),"—") -> —
A31: Punjab | B31: North | C31: =COUNTIF('CVI - All Districts'!D5:D654,"Punjab") -> 20 | D31: =COUNTIFS('CVI - All Districts'!D5:D654,"Punjab",'CVI - All Districts'!L5:L654,"<>No Data Available") -> 0 | E31: =C31-D31 -> 20 | F31: =IF(C31=0,0,D31/C31) -> 0 | G31: =IFERROR(AVERAGEIFS('CVI - All Districts'!K5:K654,'CVI - All Districts'!D5:D654,"Punjab",'CVI - All Districts'!L5:L654,"<>No Data Available"),0) -> 0 | H31: =IFERROR(maxifs('CVI - All Districts'!K5:K654,'CVI - All Districts'!D5:D654,"Punjab"),0) -> 0 | I31: =IFERROR(INDEX('CVI - All Districts'!C5:C654,MATCH(maxifs('CVI - All Districts'!K5:K654,'CVI - All Districts'!D5:D654,"Punjab"),'CVI - All Districts'!K5:K654,0)),"—") -> —
A32: Rajasthan | B32: West | C32: =COUNTIF('CVI - All Districts'!D5:D654,"Rajasthan") -> 32 | D32: =COUNTIFS('CVI - All Districts'!D5:D654,"Rajasthan",'CVI - All Districts'!L5:L654,"<>No Data Available") -> 29 | E32: =C32-D32 -> 3 | F32: =IF(C32=0,0,D32/C32) -> 0.90625 | G32: =IFERROR(AVERAGEIFS('CVI - All Districts'!K5:K654,'CVI - All Districts'!D5:D654,"Rajasthan",'CVI - All Districts'!L5:L654,"<>No Data Available"),0) -> 0.22605638 | H32: =IFERROR(maxifs('CVI - All Districts'!K5:K654,'CVI - All Districts'!D5:D654,"Rajasthan"),0) -> 0 | I32: =IFERROR(INDEX('CVI - All Districts'!C5:C654,MATCH(maxifs('CVI - All Districts'!K5:K654,'CVI - All Districts'!D5:D654,"Rajasthan"),'CVI - All Districts'!K5:K654,0)),"—") -> —
A33: Sikkim | B33: North-East | C33: =COUNTIF('CVI - All Districts'!D5:D654,"Sikkim") -> 4 | D33: =COUNTIFS('CVI - All Districts'!D5:D654,"Sikkim",'CVI - All Districts'!L5:L654,"<>No Data Available") -> 2 | E33: =C33-D33 -> 2 | F33: =IF(C33=0,0,D33/C33) -> 0.5 | G33: =IFERROR(AVERAGEIFS('CVI - All Districts'!K5:K654,'CVI - All Districts'!D5:D654,"Sikkim",'CVI - All Districts'!L5:L654,"<>No Data Available"),0) -> 0.40440115 | H33: =IFERROR(maxifs('CVI - All Districts'!K5:K654,'CVI - All Districts'!D5:D654,"Sikkim"),0) -> 0 | I33: =IFERROR(INDEX('CVI - All Districts'!C5:C654,MATCH(maxifs('CVI - All Districts'!K5:K654,'CVI - All Districts'!D5:D654,"Sikkim"),'CVI - All Districts'!K5:K654,0)),"—") -> —
A34: Tamil Nadu | B34: South | C34: =COUNTIF('CVI - All Districts'!D5:D654,"Tamil Nadu") -> 33 | D34: =COUNTIFS('CVI - All Districts'!D5:D654,"Tamil Nadu",'CVI - All Districts'!L5:L654,"<>No Data Available") -> 33 | E34: =C34-D34 -> 0 | F34: =IF(C34=0,0,D34/C34) -> 1 | G34: =IFERROR(AVERAGEIFS('CVI - All Districts'!K5:K654,'CVI - All Districts'!D5:D654,"Tamil Nadu",'CVI - All Districts'!L5:L654,"<>No Data Available"),0) -> 0.18750649 | H34: =IFERROR(maxifs('CVI - All Districts'!K5:K654,'CVI - All Districts'!D5:D654,"Tamil Nadu"),0) -> 0 | I34: =IFERROR(INDEX('CVI - All Districts'!C5:C654,MATCH(maxifs('CVI - All Districts'!K5:K654,'CVI - All Districts'!D5:D654,"Tamil Nadu"),'CVI - All Districts'!K5:K654,0)),"—") -> —
A35: Telangana | B35: South | C35: =COUNTIF('CVI - All Districts'!D5:D654,"Telangana") -> 10 | D35: =COUNTIFS('CVI - All Districts'!D5:D654,"Telangana",'CVI - All Districts'!L5:L654,"<>No Data Available") -> 10 | E35: =C35-D35 -> 0 | F35: =IF(C35=0,0,D35/C35) -> 1 | G35: =IFERROR(AVERAGEIFS('CVI - All Districts'!K5:K654,'CVI - All Districts'!D5:D654,"Telangana",'CVI - All Districts'!L5:L654,"<>No Data Available"),0) -> 0.31285073 | H35: =IFERROR(maxifs('CVI - All Districts'!K5:K654,'CVI - All Districts'!D5:D654,"Telangana"),0) -> 0 | I35: =IFERROR(INDEX('CVI - All Districts'!C5:C654,MATCH(maxifs('CVI - All Districts'!K5:K654,'CVI - All Districts'!D5:D654,"Telangana"),'CVI - All Districts'!K5:K654,0)),"—") -> —
A36: Tripura | B36: North-East | C36: =COUNTIF('CVI - All Districts'!D5:D654,"Tripura") -> 8 | D36: =COUNTIFS('CVI - All Districts'!D5:D654,"Tripura",'CVI - All Districts'!L5:L654,"<>No Data Available") -> 3 | E36: =C36-D36 -> 5 | F36: =IF(C36=0,0,D36/C36) -> 0.375 | G36: =IFERROR(AVERAGEIFS('CVI - All Districts'!K5:K654,'CVI - All Districts'!D5:D654,"Tripura",'CVI - All Districts'!L5:L654,"<>No Data Available"),0) -> 0.21814296 | H36: =IFERROR(maxifs('CVI - All Districts'!K5:K654,'CVI - All Districts'!D5:D654,"Tripura"),0) -> 0 | I36: =IFERROR(INDEX('CVI - All Districts'!C5:C654,MATCH(maxifs('CVI - All Districts'!K5:K654,'CVI - All Districts'!D5:D654,"Tripura"),'CVI - All Districts'!K5:K654,0)),"—") -> —
A37: Uttar Pradesh | B37: North | C37: =COUNTIF('CVI - All Districts'!D5:D654,"Uttar Pradesh") -> 70 | D37: =COUNTIFS('CVI - All Districts'!D5:D654,"Uttar Pradesh",'CVI - All Districts'!L5:L654,"<>No Data Available") -> 65 | E37: =C37-D37 -> 5 | F37: =IF(C37=0,0,D37/C37) -> 0.92857143 | G37: =IFERROR(AVERAGEIFS('CVI - All Districts'!K5:K654,'CVI - All Districts'!D5:D654,"Uttar Pradesh",'CVI - All Districts'!L5:L654,"<>No Data Available"),0) -> 0.16360902 | H37: =IFERROR(maxifs('CVI - All Districts'!K5:K654,'CVI - All Districts'!D5:D654,"Uttar Pradesh"),0) -> 0 | I37: =IFERROR(INDEX('CVI - All Districts'!C5:C654,MATCH(maxifs('CVI - All Districts'!K5:K654,'CVI - All Districts'!D5:D654,"Uttar Pradesh"),'CVI - All Districts'!K5:K654,0)),"—") -> —
A38: Uttarakhand | B38: North | C38: =COUNTIF('CVI - All Districts'!D5:D654,"Uttarakhand") -> 14 | D38: =COUNTIFS('CVI - All Districts'!D5:D654,"Uttarakhand",'CVI - All Districts'!L5:L654,"<>No Data Available") -> 5 | E38: =C38-D38 -> 9 | F38: =IF(C38=0,0,D38/C38) -> 0.35714286 | G38: =IFERROR(AVERAGEIFS('CVI - All Districts'!K5:K654,'CVI - All Districts'!D5:D654,"Uttarakhand",'CVI - All Districts'!L5:L654,"<>No Data Available"),0) -> 0.095941358 | H38: =IFERROR(maxifs('CVI - All Districts'!K5:K654,'CVI - All Districts'!D5:D654,"Uttarakhand"),0) -> 0 | I38: =IFERROR(INDEX('CVI - All Districts'!C5:C654,MATCH(maxifs('CVI - All Districts'!K5:K654,'CVI - All Districts'!D5:D654,"Uttarakhand"),'CVI - All Districts'!K5:K654,0)),"—") -> —
A39: West Bengal | B39: East | C39: =COUNTIF('CVI - All Districts'!D5:D654,"West Bengal") -> 21 | D39: =COUNTIFS('CVI - All Districts'!D5:D654,"West Bengal",'CVI - All Districts'!L5:L654,"<>No Data Available") -> 14 | E39: =C39-D39 -> 7 | F39: =IF(C39=0,0,D39/C39) -> 0.66666667 | G39: =IFERROR(AVERAGEIFS('CVI - All Districts'!K5:K654,'CVI - All Districts'!D5:D654,"West Bengal",'CVI - All Districts'!L5:L654,"<>No Data Available"),0) -> 0.23812037 | H39: =IFERROR(maxifs('CVI - All Districts'!K5:K654,'CVI - All Districts'!D5:D654,"West Bengal"),0) -> 0 | I39: =IFERROR(INDEX('CVI - All Districts'!C5:C654,MATCH(maxifs('CVI - All Districts'!K5:K654,'CVI - All Districts'!D5:D654,"West Bengal"),'CVI - All Districts'!K5:K654,0)),"—") -> —

Sheet Statistics
A1: CVI Dashboard Statistics
A3: Total Districts | B3: =COUNTA('CVI - All Districts'!C5:C654) -> 650
A4: Hotspot Districts (with data) | B4: =COUNTIF('CVI - All Districts'!L5:L654,"<>No Data Available") -> 471
A5: No Data Available Districts | B5: =COUNTIF('CVI - All Districts'!L5:L654,"No Data Available") -> 179
A6: % Districts Assessed | B6: =B4/B3 -> 0.72461538
A8: Avg Normalized VI (assessed) | B8: =AVERAGEIFS('CVI - All Districts'!K5:K654,'CVI - All Districts'!L5:L654,"<>No Data Available") -> 0.24208098
A9: Max Normalized VI | B9: =MAX('CVI - All Districts'!K5:K654) -> 1
A10: Median Normalized VI (assessed) | B10: =MEDIAN('CVI - All Districts'!K5:K654) -> 0.17460317
A11: Avg Exposure | B11: =AVERAGEIFS('CVI - All Districts'!G5:G654,'CVI - All Districts'!L5:L654,"<>No Data Available") -> 0.41301062
A12: Avg Sensitivity | B12: =AVERAGEIFS('CVI - All Districts'!H5:H654,'CVI - All Districts'!L5:L654,"<>No Data Available") -> 0.59473461
A13: Avg Adaptive Capacity | B13: =AVERAGEIFS('CVI - All Districts'!I5:I654,'CVI - All Districts'!L5:L654,"<>No Data Available") -> 0.43789809
A16: Vulnerability Category Breakdown
A17: Category | B17: Count | C17: % of All 650 | D17: % of Assessed
A18: Very High | B18: =COUNTIF('CVI - All Districts'!L5:L654,"Very High") -> 45 | C18: =B18/B3 -> 0.069230769 | D18: =IF(B4=0,0,IF("Very High"="No Data Available","—",B18/B4)) -> 0.095541401
A19: High | B19: =COUNTIF('CVI - All Districts'!L5:L654,"High") -> 72 | C19: =B19/B3 -> 0.11076923 | D19: =IF(B4=0,0,IF("High"="No Data Available","—",B19/B4)) -> 0.15286624
A20: Moderate | B20: =COUNTIF('CVI - All Districts'!L5:L654,"Moderate") -> 103 | C20: =B20/B3 -> 0.15846154 | D20: =IF(B4=0,0,IF("Moderate"="No Data Available","—",B20/B4)) -> 0.21868365
A21: Low | B21: =COUNTIF('CVI - All Districts'!L5:L654,"Low") -> 79 | C21: =B21/B3 -> 0.12153846 | D21: =IF(B4=0,0,IF("Low"="No Data Available","—",B21/B4)) -> 0.16772824
A22: Very Low | B22: =COUNTIF('CVI - All Districts'!L5:L654,"Very Low") -> 172 | C22: =B22/B3 -> 0.26461538 | D22: =IF(B4=0,0,IF("Very Low"="No Data Available","—",B22/B4)) -> 0.36518047
A23: No Data Available | B23: =COUNTIF('CVI - All Districts'!L5:L654,"No Data Available") -> 179 | C23: =B23/B3 -> 0.27538462 | D23: =IF(B4=0,0,IF("No Data Available"="No Data Available","—",B23/B4)) -> —
A26: Event Type Breakdown
A27: Event Type | B27: Count | C27: Avg Normalized VI
A28: Flood | B28: =COUNTIF('CVI - All Districts'!F5:F654,"Flood") -> 95 | C28: =IFERROR(AVERAGEIF('CVI - All Districts'!F5:F654,"Flood",'CVI - All Districts'!K5:K654),0) -> 0.32824771
A29: Drought | B29: =COUNTIF('CVI - All Districts'!F5:F654,"Drought") -> 186 | C29: =IFERROR(AVERAGEIF('CVI - All Districts'!F5:F654,"Drought",'CVI - All Districts'!K5:K654),0) -> 0.14648143
A30: Cyclone | B30: =COUNTIF('CVI - All Districts'!F5:F654,"Cyclone") -> 3 | C30: =IFERROR(AVERAGEIF('CVI - All Districts'!F5:F654,"Cyclone",'CVI - All Districts'!K5:K654),0) -> 0
A31: Flood & Drought | B31: =COUNTIF('CVI - All Districts'!F5:F654,"Flood & Drought") -> 114 | C31: =IFERROR(AVERAGEIF('CVI - All Districts'!F5:F654,"Flood & Drought",'CVI - All Districts'!K5:K654),0) -> 0.29139925
A32: Flood & Cyclone | B32: =COUNTIF('CVI - All Districts'!F5:F654,"Flood & Cyclone") -> 19 | C32: =IFERROR(AVERAGEIF('CVI - All Districts'!F5:F654,"Flood & Cyclone",'CVI - All Districts'!K5:K654),0) -> 0.28415773
A33: Drought & Cyclone | B33: =COUNTIF('CVI - All Districts'!F5:F654,"Drought & Cyclone") -> 12 | C33: =IFERROR(AVERAGEIF('CVI - All Districts'!F5:F654,"Drought & Cyclone",'CVI - All Districts'!K5:K654),0) -> 0.25180276
A34: Flood, Drought & Cyclone | B34: =COUNTIF('CVI - All Districts'!F5:F654,"Flood, Drought & Cyclone") -> 42 | C34: =IFERROR(AVERAGEIF('CVI - All Districts'!F5:F654,"Flood, Drought & Cyclone",'CVI - All Districts'!K5:K654),0) -> 0.33216477
A37: Zone-wise Breakdown
A38: Zone | B38: Total | C38: Assessed | D38: No Data | E38: Avg Norm VI
A39: North | B39: =COUNTIF('CVI - All Districts'!E5:E654,"North") -> 169 | C39: =COUNTIFS('CVI - All Districts'!E5:E654,"North",'CVI - All Districts'!L5:L654,"<>No Data Available") -> 99 | D39: =B39-C39 -> 70 | E39: =IFERROR(AVERAGEIFS('CVI - All Districts'!K5:K654,'CVI - All Districts'!E5:E654,"North",'CVI - All Districts'!L5:L654,"<>No Data Available"),0) -> 0.17381257
A40: South | B40: =COUNTIF('CVI - All Districts'!E5:E654,"South") -> 103 | C40: =COUNTIFS('CVI - All Districts'!E5:E654,"South",'CVI - All Districts'!L5:L654,"<>No Data Available") -> 101 | D40: =B40-C40 -> 2 | E40: =IFERROR(AVERAGEIFS('CVI - All Districts'!K5:K654,'CVI - All Districts'!E5:E654,"South",'CVI - All Districts'!L5:L654,"<>No Data Available"),0) -> 0.25679695
A41: East | B41: =COUNTIF('CVI - All Districts'!E5:E654,"East") -> 114 | C41: =COUNTIFS('CVI - All Districts'!E5:E654,"East",'CVI - All Districts'!L5:L654,"<>No Data Available") -> 93 | D41: =B41-C41 -> 21 | E41: =IFERROR(AVERAGEIFS('CVI - All Districts'!K5:K654,'CVI - All Districts'!E5:E654,"East",'CVI - All Districts'!L5:L654,"<>No Data Available"),0) -> 0.27015337
A42: West | B42: =COUNTIF('CVI - All Districts'!E5:E654,"West") -> 99 | C42: =COUNTIFS('CVI - All Districts'!E5:E654,"West",'CVI - All Districts'!L5:L654,"<>No Data Available") -> 85 | D42: =B42-C42 -> 14 | E42: =IFERROR(AVERAGEIFS('CVI - All Districts'!K5:K654,'CVI - All Districts'!E5:E654,"West",'CVI - All Districts'!L5:L654,"<>No Data Available"),0) -> 0.24964926
A43: Central | B43: =COUNTIF('CVI - All Districts'!E5:E654,"Central") -> 68 | C43: =COUNTIFS('CVI - All Districts'!E5:E654,"Central",'CVI - All Districts'!L5:L654,"<>No Data Available") -> 50 | D43: =B43-C43 -> 18 | E43: =IFERROR(AVERAGEIFS('CVI - All Districts'!K5:K654,'CVI - All Districts'!E5:E654,"Central",'CVI - All Districts'!L5:L654,"<>No Data Available"),0) -> 0.10204386
A44: North-East | B44: =COUNTIF('CVI - All Districts'!E5:E654,"North-East") -> 93 | C44: =COUNTIFS('CVI - All Districts'!E5:E654,"North-East",'CVI - All Districts'!L5:L654,"<>No Data Available") -> 41 | D44: =B44-C44 -> 52 | E44: =IFERROR(AVERAGEIFS('CVI - All Districts'!K5:K654,'CVI - All Districts'!E5:E654,"North-East",'CVI - All Districts'!L5:L654,"<>No Data Available"),0) -> 0.47389175
A45: Island | B45: =COUNTIF('CVI - All Districts'!E5:E654,"Island") -> 4 | C45: =COUNTIFS('CVI - All Districts'!E5:E654,"Island",'CVI - All Districts'!L5:L654,"<>No Data Available") -> 2 | D45: =B45-C45 -> 2 | E45: =IFERROR(AVERAGEIFS('CVI - All Districts'!K5:K654,'CVI - All Districts'!E5:E654,"Island",'CVI - All Districts'!L5:L654,"<>No Data Available"),0) -> 0

Sheet Formulas & Methodology
A1: CVI Methodology, Formulas & Data Sources
A3: CORE VULNERABILITY FORMULA
A4: Raw Vulnerability Index | B4: Raw VI = (Exposure × Sensitivity) / Adaptive Capacity
A5: Normalized VI (0–1) | B5: Norm VI = (Raw VI - Min(all Raw VI)) / (Max(all Raw VI) - Min(all Raw VI))
A7: EXPOSURE SUB-INDICES
A8: Flood Exposure | B8: Average of (Flood Frequency, Flood Intensity) over pentad decades 1970-2019
A9: Drought Exposure | B9: Average of (Drought Frequency, Drought Intensity) over pentad decades
A10: Cyclone Exposure | B10: Average of (Cyclone Frequency, Cyclone Intensity) over pentad decades
A11: Combined Exposure | B11: 0.40 × Flood + 0.35 × Drought + 0.25 × Cyclone
A13: SENSITIVITY (AHP Weights — validated via Consistency Ratio < 0.1)
A14: Flood Sensitivity | B14: 0.426×Elevation + 0.295×Slope + 0.182×LULC + 0.059×SoilMoisture + 0.037×Groundwater [CR: 0.05]
A15: Cyclone Sensitivity | B15: 0.464×LULC + 0.193×Elevation + 0.193×Slope + 0.085×SoilMoisture + 0.064×Groundwater [CR: 0.02]
A16: Drought Sensitivity | B16: 0.346×SoilMoisture + 0.293×Groundwater + 0.186×LULC + 0.099×Slope + 0.076×Elevation [CR: 0.06]
A17: Combined Sensitivity | B17: Average of disaster-specific sensitivities
A19: ADAPTIVE CAPACITY (7 indicators, equal weight)
A20: 1. Population Density | B20: Negatively correlated — inverted as (1 - normalised value)
A21: 2. GDDP | B21: Positively correlated — higher district GDP means greater shock-absorbing capacity
A22: 3. Literacy Rate | B22: Positively correlated — drives awareness, preparedness, and early response
A23: 4. Sex Ratio | B23: Negatively correlated — women disproportionately affected; inverted
A24: 5. Critical Infrastructure | B24: Positively correlated — hospitals, schools, all-weather roads
A25: 6. Disaster Shelters | B25: Positively correlated — cyclone/flood evacuation capacity
A26: 7. DDMP Score | B26: Positively correlated — governance readiness (7 sub-indicators per NDMA/SFDRR)
A28: VULNERABILITY CLASSIFICATION (based on Normalized VI)
A29: Very High | B29: Normalized VI >= 0.60
A30: High | B30: 0.40 <= Normalized VI < 0.60
A31: Moderate | B31: 0.20 <= Normalized VI < 0.40
A32: Low | B32: 0.10 <= Normalized VI < 0.20
A33: Very Low | B33: 0.00 < Normalized VI < 0.10
A34: No Data Available | B34: District not assessed as hotspot by CEEW — E, S, AC values are blank
A36: MIN-MAX NORMALIZATION
A37: Formula | B37: Norm(x) = (x - min(all_x)) / (max(all_x) - min(all_x))
A38: Applied to | B38: Raw VI column — scales all values into 0–1 range across all assessed districts
A39: Why needed | B39: Raw (E×S)/AC can exceed 1.0 when AC < E×S; normalization ensures comparable 0–1 scale
A41: DATA SOURCES
A42: Exposure | B42: CEEW Extreme Events Catalogue (1970-2019) | EM-DAT | IMD | WMO
A43: LULC | B43: ISRO-NRSC Bhuvan (temporal: 2005 & 2019)
A44: Elevation & Slope | B44: USGS SRTM DEM 30m resolution
A45: Soil Moisture | B45: NASA Giovanni 25km (temporal: 2005 & 2019)
A46: Groundwater | B46: WRIS India (Water Resources Information System)
A47: Adaptive Capacity | B47: Census of India 2011 | MoSPI | Ministry of Agriculture | PIB
...
